2025-05-16 18:09:16,314 - __main__ - INFO - Environment variables loaded
2025-05-16 18:09:16,318 - __main__ - INFO - Starting classification with model: deepseek/deepseek-chat-v3-0324:free
2025-05-16 18:09:16,319 - __main__ - INFO - Setting up OpenRouter client with key starting with: sk-or-v1-3...
2025-05-16 18:09:16,730 - __main__ - INFO - Reading messages from muthanapress84_messages.csv
2025-05-16 18:09:16,806 - __main__ - INFO - Successfully read 9215 messages from input file
2025-05-16 18:09:16,809 - __main__ - INFO - Created backup of output file at classified_messages.csv.1747408156.bak
2025-05-16 18:09:16,811 - __main__ - INFO - Processing messages 0 to 9214 out of 9215 using model deepseek/deepseek-chat-v3-0324:free
2025-05-16 18:09:16,812 - __main__ - INFO - Using OpenRouter API
2025-05-16 18:09:16,819 - __main__ - INFO - Sending request to model: deepseek/deepseek-chat-v3-0324:free
2025-05-16 18:09:17,470 - httpx - INFO - HTTP Request: POST https://openrouter.ai/api/v1/chat/completions "HTTP/1.1 200 OK"
2025-05-16 18:09:26,073 - __main__ - INFO - Received response from API
2025-05-16 18:09:26,074 - __main__ - INFO - Response content: ```json
{
    "civilian_deaths": true,
    "targeting_civilians": true,
    "blocking_aid": true,
  ...
2025-05-16 18:09:27,088 - __main__ - INFO - Sending request to model: deepseek/deepseek-chat-v3-0324:free
2025-05-16 18:09:27,199 - httpx - INFO - HTTP Request: POST https://openrouter.ai/api/v1/chat/completions "HTTP/1.1 200 OK"
2025-05-16 18:11:08,383 - __main__ - INFO - Received response from API
2025-05-16 18:11:08,386 - __main__ - INFO - Response content: ...
2025-05-16 18:11:08,389 - __main__ - ERROR - JSON parsing error: Failed to parse JSON response: line 1 column 1 (char 0)
2025-05-16 18:11:08,392 - __main__ - ERROR - Response content: 
2025-05-16 18:11:08,394 - __main__ - ERROR - JSON parsing error (attempt 1/3): Failed to parse JSON response: line 1 column 1 (char 0)
2025-05-16 18:11:10,631 - httpx - INFO - HTTP Request: POST https://openrouter.ai/api/v1/chat/completions "HTTP/1.1 200 OK"
2025-05-16 18:11:24,155 - __main__ - INFO - Received response from API
2025-05-16 18:11:24,157 - __main__ - INFO - Response content: ```json
{
    "civilian_deaths": true,
    "targeting_civilians": false,
    "blocking_aid": false,
...
2025-05-16 18:11:25,188 - __main__ - INFO - Sending request to model: deepseek/deepseek-chat-v3-0324:free
2025-05-16 18:11:25,307 - httpx - INFO - HTTP Request: POST https://openrouter.ai/api/v1/chat/completions "HTTP/1.1 200 OK"
2025-05-16 18:13:06,540 - __main__ - INFO - Received response from API
2025-05-16 18:13:06,541 - __main__ - INFO - Response content: ...
2025-05-16 18:13:06,541 - __main__ - ERROR - JSON parsing error: Failed to parse JSON response: line 1 column 1 (char 0)
2025-05-16 18:13:06,542 - __main__ - ERROR - Response content: 
2025-05-16 18:13:06,543 - __main__ - ERROR - JSON parsing error (attempt 1/3): Failed to parse JSON response: line 1 column 1 (char 0)
2025-05-16 18:13:08,894 - httpx - INFO - HTTP Request: POST https://openrouter.ai/api/v1/chat/completions "HTTP/1.1 401 Unauthorized"
2025-05-16 18:13:08,896 - __main__ - ERROR - Unexpected error: Error code: 401 - {'error': {'message': 'No auth credentials found', 'code': 401}}
2025-05-16 18:13:08,897 - __main__ - ERROR - Error during classification (attempt 2/3): Error code: 401 - {'error': {'message': 'No auth credentials found', 'code': 401}}
2025-05-16 18:13:11,137 - httpx - INFO - HTTP Request: POST https://openrouter.ai/api/v1/chat/completions "HTTP/1.1 401 Unauthorized"
2025-05-16 18:13:11,142 - __main__ - ERROR - Unexpected error: Error code: 401 - {'error': {'message': 'No auth credentials found', 'code': 401}}
2025-05-16 18:13:11,145 - __main__ - ERROR - Error during classification (attempt 3/3): Error code: 401 - {'error': {'message': 'No auth credentials found', 'code': 401}}
2025-05-16 18:13:11,148 - __main__ - ERROR - Error classifying message: Error code: 401 - {'error': {'message': 'No auth credentials found', 'code': 401}}
2025-05-16 18:13:11,162 - __main__ - ERROR - Traceback (most recent call last):
  File "C:\Users\MohamedAlcafory\Desktop\TeleScrape\classifier.py", line 237, in classify_message
    response = make_api_request(client, model, messages)
               ^^^^^^^^^^^^^^^^^^^^^^^^^^^^^^^^^^^^^^^^^
  File "C:\Users\MohamedAlcafory\Desktop\TeleScrape\classifier.py", line 83, in wrapper
    raise e
  File "C:\Users\MohamedAlcafory\Desktop\TeleScrape\classifier.py", line 57, in wrapper
    return func(*args, **kwargs)
           ^^^^^^^^^^^^^^^^^^^^^
  File "C:\Users\MohamedAlcafory\Desktop\TeleScrape\classifier.py", line 114, in make_api_request
    response = client.chat.completions.create(
               ^^^^^^^^^^^^^^^^^^^^^^^^^^^^^^^
  File "C:\Users\MohamedAlcafory\Documents\TeleScrap\.venv\Lib\site-packages\openai\_utils\_utils.py", line 287, in wrapper
    return func(*args, **kwargs)
           ^^^^^^^^^^^^^^^^^^^^^
  File "C:\Users\MohamedAlcafory\Documents\TeleScrap\.venv\Lib\site-packages\openai\resources\chat\completions\completions.py", line 925, in create
    return self._post(
           ^^^^^^^^^^^
  File "C:\Users\MohamedAlcafory\Documents\TeleScrap\.venv\Lib\site-packages\openai\_base_client.py", line 1239, in post
    return cast(ResponseT, self.request(cast_to, opts, stream=stream, stream_cls=stream_cls))
                           ^^^^^^^^^^^^^^^^^^^^^^^^^^^^^^^^^^^^^^^^^^^^^^^^^^^^^^^^^^^^^^^^^
  File "C:\Users\MohamedAlcafory\Documents\TeleScrap\.venv\Lib\site-packages\openai\_base_client.py", line 1034, in request
    raise self._make_status_error_from_response(err.response) from None
openai.AuthenticationError: Error code: 401 - {'error': {'message': 'No auth credentials found', 'code': 401}}

2025-05-16 18:13:11,178 - __main__ - ERROR - Response content: 
2025-05-16 18:13:12,190 - __main__ - INFO - Sending request to model: deepseek/deepseek-chat-v3-0324:free
2025-05-16 18:13:12,428 - httpx - INFO - HTTP Request: POST https://openrouter.ai/api/v1/chat/completions "HTTP/1.1 401 Unauthorized"
2025-05-16 18:13:12,434 - __main__ - ERROR - Unexpected error: Error code: 401 - {'error': {'message': 'No auth credentials found', 'code': 401}}
2025-05-16 18:13:12,439 - __main__ - ERROR - Error during classification (attempt 1/3): Error code: 401 - {'error': {'message': 'No auth credentials found', 'code': 401}}
2025-05-16 18:13:14,670 - httpx - INFO - HTTP Request: POST https://openrouter.ai/api/v1/chat/completions "HTTP/1.1 401 Unauthorized"
2025-05-16 18:13:14,674 - __main__ - ERROR - Unexpected error: Error code: 401 - {'error': {'message': 'No auth credentials found', 'code': 401}}
2025-05-16 18:13:14,677 - __main__ - ERROR - Error during classification (attempt 2/3): Error code: 401 - {'error': {'message': 'No auth credentials found', 'code': 401}}
2025-05-16 18:13:16,905 - httpx - INFO - HTTP Request: POST https://openrouter.ai/api/v1/chat/completions "HTTP/1.1 401 Unauthorized"
2025-05-16 18:13:16,908 - __main__ - ERROR - Unexpected error: Error code: 401 - {'error': {'message': 'No auth credentials found', 'code': 401}}
2025-05-16 18:13:16,909 - __main__ - ERROR - Error during classification (attempt 3/3): Error code: 401 - {'error': {'message': 'No auth credentials found', 'code': 401}}
2025-05-16 18:13:16,911 - __main__ - ERROR - Error classifying message: Error code: 401 - {'error': {'message': 'No auth credentials found', 'code': 401}}
2025-05-16 18:13:16,914 - __main__ - ERROR - Traceback (most recent call last):
  File "C:\Users\MohamedAlcafory\Desktop\TeleScrape\classifier.py", line 237, in classify_message
    response = make_api_request(client, model, messages)
               ^^^^^^^^^^^^^^^^^^^^^^^^^^^^^^^^^^^^^^^^^
  File "C:\Users\MohamedAlcafory\Desktop\TeleScrape\classifier.py", line 83, in wrapper
    raise e
  File "C:\Users\MohamedAlcafory\Desktop\TeleScrape\classifier.py", line 57, in wrapper
    return func(*args, **kwargs)
           ^^^^^^^^^^^^^^^^^^^^^
  File "C:\Users\MohamedAlcafory\Desktop\TeleScrape\classifier.py", line 114, in make_api_request
    response = client.chat.completions.create(
               ^^^^^^^^^^^^^^^^^^^^^^^^^^^^^^^
  File "C:\Users\MohamedAlcafory\Documents\TeleScrap\.venv\Lib\site-packages\openai\_utils\_utils.py", line 287, in wrapper
    return func(*args, **kwargs)
           ^^^^^^^^^^^^^^^^^^^^^
  File "C:\Users\MohamedAlcafory\Documents\TeleScrap\.venv\Lib\site-packages\openai\resources\chat\completions\completions.py", line 925, in create
    return self._post(
           ^^^^^^^^^^^
  File "C:\Users\MohamedAlcafory\Documents\TeleScrap\.venv\Lib\site-packages\openai\_base_client.py", line 1239, in post
    return cast(ResponseT, self.request(cast_to, opts, stream=stream, stream_cls=stream_cls))
                           ^^^^^^^^^^^^^^^^^^^^^^^^^^^^^^^^^^^^^^^^^^^^^^^^^^^^^^^^^^^^^^^^^
  File "C:\Users\MohamedAlcafory\Documents\TeleScrap\.venv\Lib\site-packages\openai\_base_client.py", line 1034, in request
    raise self._make_status_error_from_response(err.response) from None
openai.AuthenticationError: Error code: 401 - {'error': {'message': 'No auth credentials found', 'code': 401}}

2025-05-16 18:13:17,930 - __main__ - INFO - Sending request to model: deepseek/deepseek-chat-v3-0324:free
2025-05-16 18:13:18,159 - httpx - INFO - HTTP Request: POST https://openrouter.ai/api/v1/chat/completions "HTTP/1.1 401 Unauthorized"
2025-05-16 18:13:18,161 - __main__ - ERROR - Unexpected error: Error code: 401 - {'error': {'message': 'No auth credentials found', 'code': 401}}
2025-05-16 18:13:18,161 - __main__ - ERROR - Error during classification (attempt 1/3): Error code: 401 - {'error': {'message': 'No auth credentials found', 'code': 401}}
2025-05-16 18:13:20,451 - httpx - INFO - HTTP Request: POST https://openrouter.ai/api/v1/chat/completions "HTTP/1.1 401 Unauthorized"
2025-05-16 18:13:20,452 - __main__ - ERROR - Unexpected error: Error code: 401 - {'error': {'message': 'No auth credentials found', 'code': 401}}
2025-05-16 18:13:20,453 - __main__ - ERROR - Error during classification (attempt 2/3): Error code: 401 - {'error': {'message': 'No auth credentials found', 'code': 401}}
2025-05-16 18:13:22,674 - httpx - INFO - HTTP Request: POST https://openrouter.ai/api/v1/chat/completions "HTTP/1.1 401 Unauthorized"
2025-05-16 18:13:22,676 - __main__ - ERROR - Unexpected error: Error code: 401 - {'error': {'message': 'No auth credentials found', 'code': 401}}
2025-05-16 18:13:22,677 - __main__ - ERROR - Error during classification (attempt 3/3): Error code: 401 - {'error': {'message': 'No auth credentials found', 'code': 401}}
2025-05-16 18:13:22,678 - __main__ - ERROR - Error classifying message: Error code: 401 - {'error': {'message': 'No auth credentials found', 'code': 401}}
2025-05-16 18:13:22,679 - __main__ - ERROR - Traceback (most recent call last):
  File "C:\Users\MohamedAlcafory\Desktop\TeleScrape\classifier.py", line 237, in classify_message
    response = make_api_request(client, model, messages)
               ^^^^^^^^^^^^^^^^^^^^^^^^^^^^^^^^^^^^^^^^^
  File "C:\Users\MohamedAlcafory\Desktop\TeleScrape\classifier.py", line 83, in wrapper
    raise e
  File "C:\Users\MohamedAlcafory\Desktop\TeleScrape\classifier.py", line 57, in wrapper
    return func(*args, **kwargs)
           ^^^^^^^^^^^^^^^^^^^^^
  File "C:\Users\MohamedAlcafory\Desktop\TeleScrape\classifier.py", line 114, in make_api_request
    response = client.chat.completions.create(
               ^^^^^^^^^^^^^^^^^^^^^^^^^^^^^^^
  File "C:\Users\MohamedAlcafory\Documents\TeleScrap\.venv\Lib\site-packages\openai\_utils\_utils.py", line 287, in wrapper
    return func(*args, **kwargs)
           ^^^^^^^^^^^^^^^^^^^^^
  File "C:\Users\MohamedAlcafory\Documents\TeleScrap\.venv\Lib\site-packages\openai\resources\chat\completions\completions.py", line 925, in create
    return self._post(
           ^^^^^^^^^^^
  File "C:\Users\MohamedAlcafory\Documents\TeleScrap\.venv\Lib\site-packages\openai\_base_client.py", line 1239, in post
    return cast(ResponseT, self.request(cast_to, opts, stream=stream, stream_cls=stream_cls))
                           ^^^^^^^^^^^^^^^^^^^^^^^^^^^^^^^^^^^^^^^^^^^^^^^^^^^^^^^^^^^^^^^^^
  File "C:\Users\MohamedAlcafory\Documents\TeleScrap\.venv\Lib\site-packages\openai\_base_client.py", line 1034, in request
    raise self._make_status_error_from_response(err.response) from None
openai.AuthenticationError: Error code: 401 - {'error': {'message': 'No auth credentials found', 'code': 401}}

2025-05-16 18:13:23,698 - __main__ - INFO - Sending request to model: deepseek/deepseek-chat-v3-0324:free
2025-05-16 18:13:23,918 - httpx - INFO - HTTP Request: POST https://openrouter.ai/api/v1/chat/completions "HTTP/1.1 401 Unauthorized"
2025-05-16 18:13:23,919 - __main__ - ERROR - Unexpected error: Error code: 401 - {'error': {'message': 'No auth credentials found', 'code': 401}}
2025-05-16 18:13:23,920 - __main__ - ERROR - Error during classification (attempt 1/3): Error code: 401 - {'error': {'message': 'No auth credentials found', 'code': 401}}
2025-05-16 18:13:26,143 - httpx - INFO - HTTP Request: POST https://openrouter.ai/api/v1/chat/completions "HTTP/1.1 401 Unauthorized"
2025-05-16 18:13:26,144 - __main__ - ERROR - Unexpected error: Error code: 401 - {'error': {'message': 'No auth credentials found', 'code': 401}}
2025-05-16 18:13:26,145 - __main__ - ERROR - Error during classification (attempt 2/3): Error code: 401 - {'error': {'message': 'No auth credentials found', 'code': 401}}
2025-05-16 18:13:28,373 - httpx - INFO - HTTP Request: POST https://openrouter.ai/api/v1/chat/completions "HTTP/1.1 401 Unauthorized"
2025-05-16 18:13:28,376 - __main__ - ERROR - Unexpected error: Error code: 401 - {'error': {'message': 'No auth credentials found', 'code': 401}}
2025-05-16 18:13:28,377 - __main__ - ERROR - Error during classification (attempt 3/3): Error code: 401 - {'error': {'message': 'No auth credentials found', 'code': 401}}
2025-05-16 18:13:28,379 - __main__ - ERROR - Error classifying message: Error code: 401 - {'error': {'message': 'No auth credentials found', 'code': 401}}
2025-05-16 18:13:28,381 - __main__ - ERROR - Traceback (most recent call last):
  File "C:\Users\MohamedAlcafory\Desktop\TeleScrape\classifier.py", line 237, in classify_message
    response = make_api_request(client, model, messages)
               ^^^^^^^^^^^^^^^^^^^^^^^^^^^^^^^^^^^^^^^^^
  File "C:\Users\MohamedAlcafory\Desktop\TeleScrape\classifier.py", line 83, in wrapper
    raise e
  File "C:\Users\MohamedAlcafory\Desktop\TeleScrape\classifier.py", line 57, in wrapper
    return func(*args, **kwargs)
           ^^^^^^^^^^^^^^^^^^^^^
  File "C:\Users\MohamedAlcafory\Desktop\TeleScrape\classifier.py", line 114, in make_api_request
    response = client.chat.completions.create(
               ^^^^^^^^^^^^^^^^^^^^^^^^^^^^^^^
  File "C:\Users\MohamedAlcafory\Documents\TeleScrap\.venv\Lib\site-packages\openai\_utils\_utils.py", line 287, in wrapper
    return func(*args, **kwargs)
           ^^^^^^^^^^^^^^^^^^^^^
  File "C:\Users\MohamedAlcafory\Documents\TeleScrap\.venv\Lib\site-packages\openai\resources\chat\completions\completions.py", line 925, in create
    return self._post(
           ^^^^^^^^^^^
  File "C:\Users\MohamedAlcafory\Documents\TeleScrap\.venv\Lib\site-packages\openai\_base_client.py", line 1239, in post
    return cast(ResponseT, self.request(cast_to, opts, stream=stream, stream_cls=stream_cls))
                           ^^^^^^^^^^^^^^^^^^^^^^^^^^^^^^^^^^^^^^^^^^^^^^^^^^^^^^^^^^^^^^^^^
  File "C:\Users\MohamedAlcafory\Documents\TeleScrap\.venv\Lib\site-packages\openai\_base_client.py", line 1034, in request
    raise self._make_status_error_from_response(err.response) from None
openai.AuthenticationError: Error code: 401 - {'error': {'message': 'No auth credentials found', 'code': 401}}

2025-05-16 18:13:29,405 - __main__ - INFO - Sending request to model: deepseek/deepseek-chat-v3-0324:free
2025-05-16 18:13:30,551 - httpx - INFO - HTTP Request: POST https://openrouter.ai/api/v1/chat/completions "HTTP/1.1 401 Unauthorized"
2025-05-16 18:13:30,556 - __main__ - ERROR - Unexpected error: Error code: 401 - {'error': {'message': 'No auth credentials found', 'code': 401}}
2025-05-16 18:13:30,559 - __main__ - ERROR - Error during classification (attempt 1/3): Error code: 401 - {'error': {'message': 'No auth credentials found', 'code': 401}}
2025-05-16 18:13:32,796 - httpx - INFO - HTTP Request: POST https://openrouter.ai/api/v1/chat/completions "HTTP/1.1 401 Unauthorized"
2025-05-16 18:13:32,797 - __main__ - ERROR - Unexpected error: Error code: 401 - {'error': {'message': 'No auth credentials found', 'code': 401}}
2025-05-16 18:13:32,798 - __main__ - ERROR - Error during classification (attempt 2/3): Error code: 401 - {'error': {'message': 'No auth credentials found', 'code': 401}}
2025-05-16 18:13:35,043 - httpx - INFO - HTTP Request: POST https://openrouter.ai/api/v1/chat/completions "HTTP/1.1 401 Unauthorized"
2025-05-16 18:13:35,045 - __main__ - ERROR - Unexpected error: Error code: 401 - {'error': {'message': 'No auth credentials found', 'code': 401}}
2025-05-16 18:13:35,045 - __main__ - ERROR - Error during classification (attempt 3/3): Error code: 401 - {'error': {'message': 'No auth credentials found', 'code': 401}}
2025-05-16 18:13:35,046 - __main__ - ERROR - Error classifying message: Error code: 401 - {'error': {'message': 'No auth credentials found', 'code': 401}}
2025-05-16 18:13:35,047 - __main__ - ERROR - Traceback (most recent call last):
  File "C:\Users\MohamedAlcafory\Desktop\TeleScrape\classifier.py", line 237, in classify_message
    response = make_api_request(client, model, messages)
               ^^^^^^^^^^^^^^^^^^^^^^^^^^^^^^^^^^^^^^^^^
  File "C:\Users\MohamedAlcafory\Desktop\TeleScrape\classifier.py", line 83, in wrapper
    raise e
  File "C:\Users\MohamedAlcafory\Desktop\TeleScrape\classifier.py", line 57, in wrapper
    return func(*args, **kwargs)
           ^^^^^^^^^^^^^^^^^^^^^
  File "C:\Users\MohamedAlcafory\Desktop\TeleScrape\classifier.py", line 114, in make_api_request
    response = client.chat.completions.create(
               ^^^^^^^^^^^^^^^^^^^^^^^^^^^^^^^
  File "C:\Users\MohamedAlcafory\Documents\TeleScrap\.venv\Lib\site-packages\openai\_utils\_utils.py", line 287, in wrapper
    return func(*args, **kwargs)
           ^^^^^^^^^^^^^^^^^^^^^
  File "C:\Users\MohamedAlcafory\Documents\TeleScrap\.venv\Lib\site-packages\openai\resources\chat\completions\completions.py", line 925, in create
    return self._post(
           ^^^^^^^^^^^
  File "C:\Users\MohamedAlcafory\Documents\TeleScrap\.venv\Lib\site-packages\openai\_base_client.py", line 1239, in post
    return cast(ResponseT, self.request(cast_to, opts, stream=stream, stream_cls=stream_cls))
                           ^^^^^^^^^^^^^^^^^^^^^^^^^^^^^^^^^^^^^^^^^^^^^^^^^^^^^^^^^^^^^^^^^
  File "C:\Users\MohamedAlcafory\Documents\TeleScrap\.venv\Lib\site-packages\openai\_base_client.py", line 1034, in request
    raise self._make_status_error_from_response(err.response) from None
openai.AuthenticationError: Error code: 401 - {'error': {'message': 'No auth credentials found', 'code': 401}}

2025-05-16 18:13:36,064 - __main__ - INFO - Sending request to model: deepseek/deepseek-chat-v3-0324:free
2025-05-16 18:13:36,311 - httpx - INFO - HTTP Request: POST https://openrouter.ai/api/v1/chat/completions "HTTP/1.1 401 Unauthorized"
2025-05-16 18:13:36,315 - __main__ - ERROR - Unexpected error: Error code: 401 - {'error': {'message': 'No auth credentials found', 'code': 401}}
2025-05-16 18:13:36,318 - __main__ - ERROR - Error during classification (attempt 1/3): Error code: 401 - {'error': {'message': 'No auth credentials found', 'code': 401}}
2025-05-16 18:13:38,551 - httpx - INFO - HTTP Request: POST https://openrouter.ai/api/v1/chat/completions "HTTP/1.1 401 Unauthorized"
2025-05-16 18:13:38,554 - __main__ - ERROR - Unexpected error: Error code: 401 - {'error': {'message': 'No auth credentials found', 'code': 401}}
2025-05-16 18:13:38,555 - __main__ - ERROR - Error during classification (attempt 2/3): Error code: 401 - {'error': {'message': 'No auth credentials found', 'code': 401}}
2025-05-16 18:13:40,782 - httpx - INFO - HTTP Request: POST https://openrouter.ai/api/v1/chat/completions "HTTP/1.1 401 Unauthorized"
2025-05-16 18:13:40,785 - __main__ - ERROR - Unexpected error: Error code: 401 - {'error': {'message': 'No auth credentials found', 'code': 401}}
2025-05-16 18:13:40,786 - __main__ - ERROR - Error during classification (attempt 3/3): Error code: 401 - {'error': {'message': 'No auth credentials found', 'code': 401}}
2025-05-16 18:13:40,788 - __main__ - ERROR - Error classifying message: Error code: 401 - {'error': {'message': 'No auth credentials found', 'code': 401}}
2025-05-16 18:13:40,791 - __main__ - ERROR - Traceback (most recent call last):
  File "C:\Users\MohamedAlcafory\Desktop\TeleScrape\classifier.py", line 237, in classify_message
    response = make_api_request(client, model, messages)
               ^^^^^^^^^^^^^^^^^^^^^^^^^^^^^^^^^^^^^^^^^
  File "C:\Users\MohamedAlcafory\Desktop\TeleScrape\classifier.py", line 83, in wrapper
    raise e
  File "C:\Users\MohamedAlcafory\Desktop\TeleScrape\classifier.py", line 57, in wrapper
    return func(*args, **kwargs)
           ^^^^^^^^^^^^^^^^^^^^^
  File "C:\Users\MohamedAlcafory\Desktop\TeleScrape\classifier.py", line 114, in make_api_request
    response = client.chat.completions.create(
               ^^^^^^^^^^^^^^^^^^^^^^^^^^^^^^^
  File "C:\Users\MohamedAlcafory\Documents\TeleScrap\.venv\Lib\site-packages\openai\_utils\_utils.py", line 287, in wrapper
    return func(*args, **kwargs)
           ^^^^^^^^^^^^^^^^^^^^^
  File "C:\Users\MohamedAlcafory\Documents\TeleScrap\.venv\Lib\site-packages\openai\resources\chat\completions\completions.py", line 925, in create
    return self._post(
           ^^^^^^^^^^^
  File "C:\Users\MohamedAlcafory\Documents\TeleScrap\.venv\Lib\site-packages\openai\_base_client.py", line 1239, in post
    return cast(ResponseT, self.request(cast_to, opts, stream=stream, stream_cls=stream_cls))
                           ^^^^^^^^^^^^^^^^^^^^^^^^^^^^^^^^^^^^^^^^^^^^^^^^^^^^^^^^^^^^^^^^^
  File "C:\Users\MohamedAlcafory\Documents\TeleScrap\.venv\Lib\site-packages\openai\_base_client.py", line 1034, in request
    raise self._make_status_error_from_response(err.response) from None
openai.AuthenticationError: Error code: 401 - {'error': {'message': 'No auth credentials found', 'code': 401}}

2025-05-16 18:13:41,812 - __main__ - INFO - Sending request to model: deepseek/deepseek-chat-v3-0324:free
2025-05-16 18:13:42,124 - httpx - INFO - HTTP Request: POST https://openrouter.ai/api/v1/chat/completions "HTTP/1.1 401 Unauthorized"
2025-05-16 18:13:42,127 - __main__ - ERROR - Unexpected error: Error code: 401 - {'error': {'message': 'No auth credentials found', 'code': 401}}
2025-05-16 18:13:42,129 - __main__ - ERROR - Error during classification (attempt 1/3): Error code: 401 - {'error': {'message': 'No auth credentials found', 'code': 401}}
2025-05-16 18:13:44,352 - httpx - INFO - HTTP Request: POST https://openrouter.ai/api/v1/chat/completions "HTTP/1.1 401 Unauthorized"
2025-05-16 18:13:44,354 - __main__ - ERROR - Unexpected error: Error code: 401 - {'error': {'message': 'No auth credentials found', 'code': 401}}
2025-05-16 18:13:44,354 - __main__ - ERROR - Error during classification (attempt 2/3): Error code: 401 - {'error': {'message': 'No auth credentials found', 'code': 401}}
2025-05-16 18:13:46,560 - httpx - INFO - HTTP Request: POST https://openrouter.ai/api/v1/chat/completions "HTTP/1.1 401 Unauthorized"
2025-05-16 18:13:46,561 - __main__ - ERROR - Unexpected error: Error code: 401 - {'error': {'message': 'No auth credentials found', 'code': 401}}
2025-05-16 18:13:46,561 - __main__ - ERROR - Error during classification (attempt 3/3): Error code: 401 - {'error': {'message': 'No auth credentials found', 'code': 401}}
2025-05-16 18:13:46,562 - __main__ - ERROR - Error classifying message: Error code: 401 - {'error': {'message': 'No auth credentials found', 'code': 401}}
2025-05-16 18:13:46,563 - __main__ - ERROR - Traceback (most recent call last):
  File "C:\Users\MohamedAlcafory\Desktop\TeleScrape\classifier.py", line 237, in classify_message
    response = make_api_request(client, model, messages)
               ^^^^^^^^^^^^^^^^^^^^^^^^^^^^^^^^^^^^^^^^^
  File "C:\Users\MohamedAlcafory\Desktop\TeleScrape\classifier.py", line 83, in wrapper
    raise e
  File "C:\Users\MohamedAlcafory\Desktop\TeleScrape\classifier.py", line 57, in wrapper
    return func(*args, **kwargs)
           ^^^^^^^^^^^^^^^^^^^^^
  File "C:\Users\MohamedAlcafory\Desktop\TeleScrape\classifier.py", line 114, in make_api_request
    response = client.chat.completions.create(
               ^^^^^^^^^^^^^^^^^^^^^^^^^^^^^^^
  File "C:\Users\MohamedAlcafory\Documents\TeleScrap\.venv\Lib\site-packages\openai\_utils\_utils.py", line 287, in wrapper
    return func(*args, **kwargs)
           ^^^^^^^^^^^^^^^^^^^^^
  File "C:\Users\MohamedAlcafory\Documents\TeleScrap\.venv\Lib\site-packages\openai\resources\chat\completions\completions.py", line 925, in create
    return self._post(
           ^^^^^^^^^^^
  File "C:\Users\MohamedAlcafory\Documents\TeleScrap\.venv\Lib\site-packages\openai\_base_client.py", line 1239, in post
    return cast(ResponseT, self.request(cast_to, opts, stream=stream, stream_cls=stream_cls))
                           ^^^^^^^^^^^^^^^^^^^^^^^^^^^^^^^^^^^^^^^^^^^^^^^^^^^^^^^^^^^^^^^^^
  File "C:\Users\MohamedAlcafory\Documents\TeleScrap\.venv\Lib\site-packages\openai\_base_client.py", line 1034, in request
    raise self._make_status_error_from_response(err.response) from None
openai.AuthenticationError: Error code: 401 - {'error': {'message': 'No auth credentials found', 'code': 401}}

2025-05-16 18:13:47,585 - __main__ - WARNING - Skipping empty message at index 9
2025-05-16 18:13:47,590 - __main__ - INFO - Sending request to model: deepseek/deepseek-chat-v3-0324:free
2025-05-16 18:13:47,826 - httpx - INFO - HTTP Request: POST https://openrouter.ai/api/v1/chat/completions "HTTP/1.1 401 Unauthorized"
2025-05-16 18:13:47,828 - __main__ - ERROR - Unexpected error: Error code: 401 - {'error': {'message': 'No auth credentials found', 'code': 401}}
2025-05-16 18:13:47,828 - __main__ - ERROR - Error during classification (attempt 1/3): Error code: 401 - {'error': {'message': 'No auth credentials found', 'code': 401}}
2025-05-16 18:13:50,069 - httpx - INFO - HTTP Request: POST https://openrouter.ai/api/v1/chat/completions "HTTP/1.1 401 Unauthorized"
2025-05-16 18:13:50,071 - __main__ - ERROR - Unexpected error: Error code: 401 - {'error': {'message': 'No auth credentials found', 'code': 401}}
2025-05-16 18:13:50,072 - __main__ - ERROR - Error during classification (attempt 2/3): Error code: 401 - {'error': {'message': 'No auth credentials found', 'code': 401}}
2025-05-16 18:13:52,318 - httpx - INFO - HTTP Request: POST https://openrouter.ai/api/v1/chat/completions "HTTP/1.1 401 Unauthorized"
2025-05-16 18:13:52,319 - __main__ - ERROR - Unexpected error: Error code: 401 - {'error': {'message': 'No auth credentials found', 'code': 401}}
2025-05-16 18:13:52,320 - __main__ - ERROR - Error during classification (attempt 3/3): Error code: 401 - {'error': {'message': 'No auth credentials found', 'code': 401}}
2025-05-16 18:13:52,320 - __main__ - ERROR - Error classifying message: Error code: 401 - {'error': {'message': 'No auth credentials found', 'code': 401}}
2025-05-16 18:13:52,322 - __main__ - ERROR - Traceback (most recent call last):
  File "C:\Users\MohamedAlcafory\Desktop\TeleScrape\classifier.py", line 237, in classify_message
    response = make_api_request(client, model, messages)
               ^^^^^^^^^^^^^^^^^^^^^^^^^^^^^^^^^^^^^^^^^
  File "C:\Users\MohamedAlcafory\Desktop\TeleScrape\classifier.py", line 83, in wrapper
    raise e
  File "C:\Users\MohamedAlcafory\Desktop\TeleScrape\classifier.py", line 57, in wrapper
    return func(*args, **kwargs)
           ^^^^^^^^^^^^^^^^^^^^^
  File "C:\Users\MohamedAlcafory\Desktop\TeleScrape\classifier.py", line 114, in make_api_request
    response = client.chat.completions.create(
               ^^^^^^^^^^^^^^^^^^^^^^^^^^^^^^^
  File "C:\Users\MohamedAlcafory\Documents\TeleScrap\.venv\Lib\site-packages\openai\_utils\_utils.py", line 287, in wrapper
    return func(*args, **kwargs)
           ^^^^^^^^^^^^^^^^^^^^^
  File "C:\Users\MohamedAlcafory\Documents\TeleScrap\.venv\Lib\site-packages\openai\resources\chat\completions\completions.py", line 925, in create
    return self._post(
           ^^^^^^^^^^^
  File "C:\Users\MohamedAlcafory\Documents\TeleScrap\.venv\Lib\site-packages\openai\_base_client.py", line 1239, in post
    return cast(ResponseT, self.request(cast_to, opts, stream=stream, stream_cls=stream_cls))
                           ^^^^^^^^^^^^^^^^^^^^^^^^^^^^^^^^^^^^^^^^^^^^^^^^^^^^^^^^^^^^^^^^^
  File "C:\Users\MohamedAlcafory\Documents\TeleScrap\.venv\Lib\site-packages\openai\_base_client.py", line 1034, in request
    raise self._make_status_error_from_response(err.response) from None
openai.AuthenticationError: Error code: 401 - {'error': {'message': 'No auth credentials found', 'code': 401}}

2025-05-16 18:13:52,337 - __main__ - INFO - Progress: 11/9215 messages processed. Success: 10, Failed: 0, Genocidal: 2, Official Speeches: 1
2025-05-16 18:13:53,340 - __main__ - INFO - Sending request to model: deepseek/deepseek-chat-v3-0324:free
2025-05-16 18:13:53,569 - httpx - INFO - HTTP Request: POST https://openrouter.ai/api/v1/chat/completions "HTTP/1.1 401 Unauthorized"
2025-05-16 18:13:53,570 - __main__ - ERROR - Unexpected error: Error code: 401 - {'error': {'message': 'No auth credentials found', 'code': 401}}
2025-05-16 18:13:53,571 - __main__ - ERROR - Error during classification (attempt 1/3): Error code: 401 - {'error': {'message': 'No auth credentials found', 'code': 401}}
2025-05-16 18:13:55,790 - httpx - INFO - HTTP Request: POST https://openrouter.ai/api/v1/chat/completions "HTTP/1.1 401 Unauthorized"
2025-05-16 18:13:55,794 - __main__ - ERROR - Unexpected error: Error code: 401 - {'error': {'message': 'No auth credentials found', 'code': 401}}
2025-05-16 18:13:55,797 - __main__ - ERROR - Error during classification (attempt 2/3): Error code: 401 - {'error': {'message': 'No auth credentials found', 'code': 401}}
2025-05-16 18:13:58,088 - httpx - INFO - HTTP Request: POST https://openrouter.ai/api/v1/chat/completions "HTTP/1.1 401 Unauthorized"
2025-05-16 18:13:58,092 - __main__ - ERROR - Unexpected error: Error code: 401 - {'error': {'message': 'No auth credentials found', 'code': 401}}
2025-05-16 18:13:58,094 - __main__ - ERROR - Error during classification (attempt 3/3): Error code: 401 - {'error': {'message': 'No auth credentials found', 'code': 401}}
2025-05-16 18:13:58,098 - __main__ - ERROR - Error classifying message: Error code: 401 - {'error': {'message': 'No auth credentials found', 'code': 401}}
2025-05-16 18:13:58,103 - __main__ - ERROR - Traceback (most recent call last):
  File "C:\Users\MohamedAlcafory\Desktop\TeleScrape\classifier.py", line 237, in classify_message
    response = make_api_request(client, model, messages)
               ^^^^^^^^^^^^^^^^^^^^^^^^^^^^^^^^^^^^^^^^^
  File "C:\Users\MohamedAlcafory\Desktop\TeleScrape\classifier.py", line 83, in wrapper
    raise e
  File "C:\Users\MohamedAlcafory\Desktop\TeleScrape\classifier.py", line 57, in wrapper
    return func(*args, **kwargs)
           ^^^^^^^^^^^^^^^^^^^^^
  File "C:\Users\MohamedAlcafory\Desktop\TeleScrape\classifier.py", line 114, in make_api_request
    response = client.chat.completions.create(
               ^^^^^^^^^^^^^^^^^^^^^^^^^^^^^^^
  File "C:\Users\MohamedAlcafory\Documents\TeleScrap\.venv\Lib\site-packages\openai\_utils\_utils.py", line 287, in wrapper
    return func(*args, **kwargs)
           ^^^^^^^^^^^^^^^^^^^^^
  File "C:\Users\MohamedAlcafory\Documents\TeleScrap\.venv\Lib\site-packages\openai\resources\chat\completions\completions.py", line 925, in create
    return self._post(
           ^^^^^^^^^^^
  File "C:\Users\MohamedAlcafory\Documents\TeleScrap\.venv\Lib\site-packages\openai\_base_client.py", line 1239, in post
    return cast(ResponseT, self.request(cast_to, opts, stream=stream, stream_cls=stream_cls))
                           ^^^^^^^^^^^^^^^^^^^^^^^^^^^^^^^^^^^^^^^^^^^^^^^^^^^^^^^^^^^^^^^^^
  File "C:\Users\MohamedAlcafory\Documents\TeleScrap\.venv\Lib\site-packages\openai\_base_client.py", line 1034, in request
    raise self._make_status_error_from_response(err.response) from None
openai.AuthenticationError: Error code: 401 - {'error': {'message': 'No auth credentials found', 'code': 401}}

2025-05-16 18:13:59,136 - __main__ - INFO - Sending request to model: deepseek/deepseek-chat-v3-0324:free
2025-05-16 18:13:59,357 - httpx - INFO - HTTP Request: POST https://openrouter.ai/api/v1/chat/completions "HTTP/1.1 401 Unauthorized"
2025-05-16 18:13:59,358 - __main__ - ERROR - Unexpected error: Error code: 401 - {'error': {'message': 'No auth credentials found', 'code': 401}}
2025-05-16 18:13:59,359 - __main__ - ERROR - Error during classification (attempt 1/3): Error code: 401 - {'error': {'message': 'No auth credentials found', 'code': 401}}
2025-05-16 18:14:01,585 - httpx - INFO - HTTP Request: POST https://openrouter.ai/api/v1/chat/completions "HTTP/1.1 401 Unauthorized"
2025-05-16 18:14:01,587 - __main__ - ERROR - Unexpected error: Error code: 401 - {'error': {'message': 'No auth credentials found', 'code': 401}}
2025-05-16 18:14:01,588 - __main__ - ERROR - Error during classification (attempt 2/3): Error code: 401 - {'error': {'message': 'No auth credentials found', 'code': 401}}
2025-05-16 18:14:03,813 - httpx - INFO - HTTP Request: POST https://openrouter.ai/api/v1/chat/completions "HTTP/1.1 401 Unauthorized"
2025-05-16 18:14:03,815 - __main__ - ERROR - Unexpected error: Error code: 401 - {'error': {'message': 'No auth credentials found', 'code': 401}}
2025-05-16 18:14:03,816 - __main__ - ERROR - Error during classification (attempt 3/3): Error code: 401 - {'error': {'message': 'No auth credentials found', 'code': 401}}
2025-05-16 18:14:03,818 - __main__ - ERROR - Error classifying message: Error code: 401 - {'error': {'message': 'No auth credentials found', 'code': 401}}
2025-05-16 18:14:03,820 - __main__ - ERROR - Traceback (most recent call last):
  File "C:\Users\MohamedAlcafory\Desktop\TeleScrape\classifier.py", line 237, in classify_message
    response = make_api_request(client, model, messages)
               ^^^^^^^^^^^^^^^^^^^^^^^^^^^^^^^^^^^^^^^^^
  File "C:\Users\MohamedAlcafory\Desktop\TeleScrape\classifier.py", line 83, in wrapper
    raise e
  File "C:\Users\MohamedAlcafory\Desktop\TeleScrape\classifier.py", line 57, in wrapper
    return func(*args, **kwargs)
           ^^^^^^^^^^^^^^^^^^^^^
  File "C:\Users\MohamedAlcafory\Desktop\TeleScrape\classifier.py", line 114, in make_api_request
    response = client.chat.completions.create(
               ^^^^^^^^^^^^^^^^^^^^^^^^^^^^^^^
  File "C:\Users\MohamedAlcafory\Documents\TeleScrap\.venv\Lib\site-packages\openai\_utils\_utils.py", line 287, in wrapper
    return func(*args, **kwargs)
           ^^^^^^^^^^^^^^^^^^^^^
  File "C:\Users\MohamedAlcafory\Documents\TeleScrap\.venv\Lib\site-packages\openai\resources\chat\completions\completions.py", line 925, in create
    return self._post(
           ^^^^^^^^^^^
  File "C:\Users\MohamedAlcafory\Documents\TeleScrap\.venv\Lib\site-packages\openai\_base_client.py", line 1239, in post
    return cast(ResponseT, self.request(cast_to, opts, stream=stream, stream_cls=stream_cls))
                           ^^^^^^^^^^^^^^^^^^^^^^^^^^^^^^^^^^^^^^^^^^^^^^^^^^^^^^^^^^^^^^^^^
  File "C:\Users\MohamedAlcafory\Documents\TeleScrap\.venv\Lib\site-packages\openai\_base_client.py", line 1034, in request
    raise self._make_status_error_from_response(err.response) from None
openai.AuthenticationError: Error code: 401 - {'error': {'message': 'No auth credentials found', 'code': 401}}

2025-05-16 18:14:04,837 - __main__ - INFO - Sending request to model: deepseek/deepseek-chat-v3-0324:free
2025-05-16 18:14:05,056 - httpx - INFO - HTTP Request: POST https://openrouter.ai/api/v1/chat/completions "HTTP/1.1 401 Unauthorized"
2025-05-16 18:14:05,061 - __main__ - ERROR - Unexpected error: Error code: 401 - {'error': {'message': 'No auth credentials found', 'code': 401}}
2025-05-16 18:14:05,065 - __main__ - ERROR - Error during classification (attempt 1/3): Error code: 401 - {'error': {'message': 'No auth credentials found', 'code': 401}}
2025-05-16 18:14:07,321 - httpx - INFO - HTTP Request: POST https://openrouter.ai/api/v1/chat/completions "HTTP/1.1 401 Unauthorized"
2025-05-16 18:14:07,324 - __main__ - ERROR - Unexpected error: Error code: 401 - {'error': {'message': 'No auth credentials found', 'code': 401}}
2025-05-16 18:14:07,326 - __main__ - ERROR - Error during classification (attempt 2/3): Error code: 401 - {'error': {'message': 'No auth credentials found', 'code': 401}}
2025-05-16 18:14:09,570 - httpx - INFO - HTTP Request: POST https://openrouter.ai/api/v1/chat/completions "HTTP/1.1 401 Unauthorized"
2025-05-16 18:14:09,573 - __main__ - ERROR - Unexpected error: Error code: 401 - {'error': {'message': 'No auth credentials found', 'code': 401}}
2025-05-16 18:14:09,576 - __main__ - ERROR - Error during classification (attempt 3/3): Error code: 401 - {'error': {'message': 'No auth credentials found', 'code': 401}}
2025-05-16 18:14:09,577 - __main__ - ERROR - Error classifying message: Error code: 401 - {'error': {'message': 'No auth credentials found', 'code': 401}}
2025-05-16 18:14:09,581 - __main__ - ERROR - Traceback (most recent call last):
  File "C:\Users\MohamedAlcafory\Desktop\TeleScrape\classifier.py", line 237, in classify_message
    response = make_api_request(client, model, messages)
               ^^^^^^^^^^^^^^^^^^^^^^^^^^^^^^^^^^^^^^^^^
  File "C:\Users\MohamedAlcafory\Desktop\TeleScrape\classifier.py", line 83, in wrapper
    raise e
  File "C:\Users\MohamedAlcafory\Desktop\TeleScrape\classifier.py", line 57, in wrapper
    return func(*args, **kwargs)
           ^^^^^^^^^^^^^^^^^^^^^
  File "C:\Users\MohamedAlcafory\Desktop\TeleScrape\classifier.py", line 114, in make_api_request
    response = client.chat.completions.create(
               ^^^^^^^^^^^^^^^^^^^^^^^^^^^^^^^
  File "C:\Users\MohamedAlcafory\Documents\TeleScrap\.venv\Lib\site-packages\openai\_utils\_utils.py", line 287, in wrapper
    return func(*args, **kwargs)
           ^^^^^^^^^^^^^^^^^^^^^
  File "C:\Users\MohamedAlcafory\Documents\TeleScrap\.venv\Lib\site-packages\openai\resources\chat\completions\completions.py", line 925, in create
    return self._post(
           ^^^^^^^^^^^
  File "C:\Users\MohamedAlcafory\Documents\TeleScrap\.venv\Lib\site-packages\openai\_base_client.py", line 1239, in post
    return cast(ResponseT, self.request(cast_to, opts, stream=stream, stream_cls=stream_cls))
                           ^^^^^^^^^^^^^^^^^^^^^^^^^^^^^^^^^^^^^^^^^^^^^^^^^^^^^^^^^^^^^^^^^
  File "C:\Users\MohamedAlcafory\Documents\TeleScrap\.venv\Lib\site-packages\openai\_base_client.py", line 1034, in request
    raise self._make_status_error_from_response(err.response) from None
openai.AuthenticationError: Error code: 401 - {'error': {'message': 'No auth credentials found', 'code': 401}}

2025-05-16 18:14:10,601 - __main__ - INFO - Sending request to model: deepseek/deepseek-chat-v3-0324:free
2025-05-16 18:14:10,831 - httpx - INFO - HTTP Request: POST https://openrouter.ai/api/v1/chat/completions "HTTP/1.1 401 Unauthorized"
2025-05-16 18:14:10,833 - __main__ - ERROR - Unexpected error: Error code: 401 - {'error': {'message': 'No auth credentials found', 'code': 401}}
2025-05-16 18:14:10,833 - __main__ - ERROR - Error during classification (attempt 1/3): Error code: 401 - {'error': {'message': 'No auth credentials found', 'code': 401}}
2025-05-16 18:14:13,062 - httpx - INFO - HTTP Request: POST https://openrouter.ai/api/v1/chat/completions "HTTP/1.1 401 Unauthorized"
2025-05-16 18:14:13,065 - __main__ - ERROR - Unexpected error: Error code: 401 - {'error': {'message': 'No auth credentials found', 'code': 401}}
2025-05-16 18:14:13,067 - __main__ - ERROR - Error during classification (attempt 2/3): Error code: 401 - {'error': {'message': 'No auth credentials found', 'code': 401}}
2025-05-16 18:14:15,280 - httpx - INFO - HTTP Request: POST https://openrouter.ai/api/v1/chat/completions "HTTP/1.1 401 Unauthorized"
2025-05-16 18:14:15,283 - __main__ - ERROR - Unexpected error: Error code: 401 - {'error': {'message': 'No auth credentials found', 'code': 401}}
2025-05-16 18:14:15,284 - __main__ - ERROR - Error during classification (attempt 3/3): Error code: 401 - {'error': {'message': 'No auth credentials found', 'code': 401}}
2025-05-16 18:14:15,286 - __main__ - ERROR - Error classifying message: Error code: 401 - {'error': {'message': 'No auth credentials found', 'code': 401}}
2025-05-16 18:14:15,289 - __main__ - ERROR - Traceback (most recent call last):
  File "C:\Users\MohamedAlcafory\Desktop\TeleScrape\classifier.py", line 237, in classify_message
    response = make_api_request(client, model, messages)
               ^^^^^^^^^^^^^^^^^^^^^^^^^^^^^^^^^^^^^^^^^
  File "C:\Users\MohamedAlcafory\Desktop\TeleScrape\classifier.py", line 83, in wrapper
    raise e
  File "C:\Users\MohamedAlcafory\Desktop\TeleScrape\classifier.py", line 57, in wrapper
    return func(*args, **kwargs)
           ^^^^^^^^^^^^^^^^^^^^^
  File "C:\Users\MohamedAlcafory\Desktop\TeleScrape\classifier.py", line 114, in make_api_request
    response = client.chat.completions.create(
               ^^^^^^^^^^^^^^^^^^^^^^^^^^^^^^^
  File "C:\Users\MohamedAlcafory\Documents\TeleScrap\.venv\Lib\site-packages\openai\_utils\_utils.py", line 287, in wrapper
    return func(*args, **kwargs)
           ^^^^^^^^^^^^^^^^^^^^^
  File "C:\Users\MohamedAlcafory\Documents\TeleScrap\.venv\Lib\site-packages\openai\resources\chat\completions\completions.py", line 925, in create
    return self._post(
           ^^^^^^^^^^^
  File "C:\Users\MohamedAlcafory\Documents\TeleScrap\.venv\Lib\site-packages\openai\_base_client.py", line 1239, in post
    return cast(ResponseT, self.request(cast_to, opts, stream=stream, stream_cls=stream_cls))
                           ^^^^^^^^^^^^^^^^^^^^^^^^^^^^^^^^^^^^^^^^^^^^^^^^^^^^^^^^^^^^^^^^^
  File "C:\Users\MohamedAlcafory\Documents\TeleScrap\.venv\Lib\site-packages\openai\_base_client.py", line 1034, in request
    raise self._make_status_error_from_response(err.response) from None
openai.AuthenticationError: Error code: 401 - {'error': {'message': 'No auth credentials found', 'code': 401}}

2025-05-16 18:14:16,308 - __main__ - INFO - Sending request to model: deepseek/deepseek-chat-v3-0324:free
2025-05-16 18:14:16,530 - httpx - INFO - HTTP Request: POST https://openrouter.ai/api/v1/chat/completions "HTTP/1.1 401 Unauthorized"
2025-05-16 18:14:16,531 - __main__ - ERROR - Unexpected error: Error code: 401 - {'error': {'message': 'No auth credentials found', 'code': 401}}
2025-05-16 18:14:16,532 - __main__ - ERROR - Error during classification (attempt 1/3): Error code: 401 - {'error': {'message': 'No auth credentials found', 'code': 401}}
2025-05-16 18:14:18,808 - httpx - INFO - HTTP Request: POST https://openrouter.ai/api/v1/chat/completions "HTTP/1.1 401 Unauthorized"
2025-05-16 18:14:18,809 - __main__ - ERROR - Unexpected error: Error code: 401 - {'error': {'message': 'No auth credentials found', 'code': 401}}
2025-05-16 18:14:18,811 - __main__ - ERROR - Error during classification (attempt 2/3): Error code: 401 - {'error': {'message': 'No auth credentials found', 'code': 401}}
2025-05-16 18:14:21,046 - httpx - INFO - HTTP Request: POST https://openrouter.ai/api/v1/chat/completions "HTTP/1.1 401 Unauthorized"
2025-05-16 18:14:21,047 - __main__ - ERROR - Unexpected error: Error code: 401 - {'error': {'message': 'No auth credentials found', 'code': 401}}
2025-05-16 18:14:21,047 - __main__ - ERROR - Error during classification (attempt 3/3): Error code: 401 - {'error': {'message': 'No auth credentials found', 'code': 401}}
2025-05-16 18:14:21,048 - __main__ - ERROR - Error classifying message: Error code: 401 - {'error': {'message': 'No auth credentials found', 'code': 401}}
2025-05-16 18:14:21,049 - __main__ - ERROR - Traceback (most recent call last):
  File "C:\Users\MohamedAlcafory\Desktop\TeleScrape\classifier.py", line 237, in classify_message
    response = make_api_request(client, model, messages)
               ^^^^^^^^^^^^^^^^^^^^^^^^^^^^^^^^^^^^^^^^^
  File "C:\Users\MohamedAlcafory\Desktop\TeleScrape\classifier.py", line 83, in wrapper
    raise e
  File "C:\Users\MohamedAlcafory\Desktop\TeleScrape\classifier.py", line 57, in wrapper
    return func(*args, **kwargs)
           ^^^^^^^^^^^^^^^^^^^^^
  File "C:\Users\MohamedAlcafory\Desktop\TeleScrape\classifier.py", line 114, in make_api_request
    response = client.chat.completions.create(
               ^^^^^^^^^^^^^^^^^^^^^^^^^^^^^^^
  File "C:\Users\MohamedAlcafory\Documents\TeleScrap\.venv\Lib\site-packages\openai\_utils\_utils.py", line 287, in wrapper
    return func(*args, **kwargs)
           ^^^^^^^^^^^^^^^^^^^^^
  File "C:\Users\MohamedAlcafory\Documents\TeleScrap\.venv\Lib\site-packages\openai\resources\chat\completions\completions.py", line 925, in create
    return self._post(
           ^^^^^^^^^^^
  File "C:\Users\MohamedAlcafory\Documents\TeleScrap\.venv\Lib\site-packages\openai\_base_client.py", line 1239, in post
    return cast(ResponseT, self.request(cast_to, opts, stream=stream, stream_cls=stream_cls))
                           ^^^^^^^^^^^^^^^^^^^^^^^^^^^^^^^^^^^^^^^^^^^^^^^^^^^^^^^^^^^^^^^^^
  File "C:\Users\MohamedAlcafory\Documents\TeleScrap\.venv\Lib\site-packages\openai\_base_client.py", line 1034, in request
    raise self._make_status_error_from_response(err.response) from None
openai.AuthenticationError: Error code: 401 - {'error': {'message': 'No auth credentials found', 'code': 401}}

2025-05-16 18:14:22,067 - __main__ - INFO - Sending request to model: deepseek/deepseek-chat-v3-0324:free
2025-05-16 18:14:22,304 - httpx - INFO - HTTP Request: POST https://openrouter.ai/api/v1/chat/completions "HTTP/1.1 401 Unauthorized"
2025-05-16 18:14:22,306 - __main__ - ERROR - Unexpected error: Error code: 401 - {'error': {'message': 'No auth credentials found', 'code': 401}}
2025-05-16 18:14:22,306 - __main__ - ERROR - Error during classification (attempt 1/3): Error code: 401 - {'error': {'message': 'No auth credentials found', 'code': 401}}
2025-05-16 18:14:24,618 - httpx - INFO - HTTP Request: POST https://openrouter.ai/api/v1/chat/completions "HTTP/1.1 401 Unauthorized"
2025-05-16 18:14:24,620 - __main__ - ERROR - Unexpected error: Error code: 401 - {'error': {'message': 'No auth credentials found', 'code': 401}}
2025-05-16 18:14:24,622 - __main__ - ERROR - Error during classification (attempt 2/3): Error code: 401 - {'error': {'message': 'No auth credentials found', 'code': 401}}
2025-05-16 18:14:26,891 - httpx - INFO - HTTP Request: POST https://openrouter.ai/api/v1/chat/completions "HTTP/1.1 401 Unauthorized"
2025-05-16 18:14:26,895 - __main__ - ERROR - Unexpected error: Error code: 401 - {'error': {'message': 'No auth credentials found', 'code': 401}}
2025-05-16 18:14:26,896 - __main__ - ERROR - Error during classification (attempt 3/3): Error code: 401 - {'error': {'message': 'No auth credentials found', 'code': 401}}
2025-05-16 18:14:26,898 - __main__ - ERROR - Error classifying message: Error code: 401 - {'error': {'message': 'No auth credentials found', 'code': 401}}
2025-05-16 18:14:26,901 - __main__ - ERROR - Traceback (most recent call last):
  File "C:\Users\MohamedAlcafory\Desktop\TeleScrape\classifier.py", line 237, in classify_message
    response = make_api_request(client, model, messages)
               ^^^^^^^^^^^^^^^^^^^^^^^^^^^^^^^^^^^^^^^^^
  File "C:\Users\MohamedAlcafory\Desktop\TeleScrape\classifier.py", line 83, in wrapper
    raise e
  File "C:\Users\MohamedAlcafory\Desktop\TeleScrape\classifier.py", line 57, in wrapper
    return func(*args, **kwargs)
           ^^^^^^^^^^^^^^^^^^^^^
  File "C:\Users\MohamedAlcafory\Desktop\TeleScrape\classifier.py", line 114, in make_api_request
    response = client.chat.completions.create(
               ^^^^^^^^^^^^^^^^^^^^^^^^^^^^^^^
  File "C:\Users\MohamedAlcafory\Documents\TeleScrap\.venv\Lib\site-packages\openai\_utils\_utils.py", line 287, in wrapper
    return func(*args, **kwargs)
           ^^^^^^^^^^^^^^^^^^^^^
  File "C:\Users\MohamedAlcafory\Documents\TeleScrap\.venv\Lib\site-packages\openai\resources\chat\completions\completions.py", line 925, in create
    return self._post(
           ^^^^^^^^^^^
  File "C:\Users\MohamedAlcafory\Documents\TeleScrap\.venv\Lib\site-packages\openai\_base_client.py", line 1239, in post
    return cast(ResponseT, self.request(cast_to, opts, stream=stream, stream_cls=stream_cls))
                           ^^^^^^^^^^^^^^^^^^^^^^^^^^^^^^^^^^^^^^^^^^^^^^^^^^^^^^^^^^^^^^^^^
  File "C:\Users\MohamedAlcafory\Documents\TeleScrap\.venv\Lib\site-packages\openai\_base_client.py", line 1034, in request
    raise self._make_status_error_from_response(err.response) from None
openai.AuthenticationError: Error code: 401 - {'error': {'message': 'No auth credentials found', 'code': 401}}

2025-05-16 18:14:27,922 - __main__ - INFO - Sending request to model: deepseek/deepseek-chat-v3-0324:free
2025-05-16 18:14:28,178 - httpx - INFO - HTTP Request: POST https://openrouter.ai/api/v1/chat/completions "HTTP/1.1 401 Unauthorized"
2025-05-16 18:14:28,179 - __main__ - ERROR - Unexpected error: Error code: 401 - {'error': {'message': 'No auth credentials found', 'code': 401}}
2025-05-16 18:14:28,180 - __main__ - ERROR - Error during classification (attempt 1/3): Error code: 401 - {'error': {'message': 'No auth credentials found', 'code': 401}}
2025-05-16 18:14:30,409 - httpx - INFO - HTTP Request: POST https://openrouter.ai/api/v1/chat/completions "HTTP/1.1 401 Unauthorized"
2025-05-16 18:14:30,411 - __main__ - ERROR - Unexpected error: Error code: 401 - {'error': {'message': 'No auth credentials found', 'code': 401}}
2025-05-16 18:14:30,412 - __main__ - ERROR - Error during classification (attempt 2/3): Error code: 401 - {'error': {'message': 'No auth credentials found', 'code': 401}}
2025-05-16 18:14:32,628 - httpx - INFO - HTTP Request: POST https://openrouter.ai/api/v1/chat/completions "HTTP/1.1 401 Unauthorized"
2025-05-16 18:14:32,631 - __main__ - ERROR - Unexpected error: Error code: 401 - {'error': {'message': 'No auth credentials found', 'code': 401}}
2025-05-16 18:14:32,634 - __main__ - ERROR - Error during classification (attempt 3/3): Error code: 401 - {'error': {'message': 'No auth credentials found', 'code': 401}}
2025-05-16 18:14:32,636 - __main__ - ERROR - Error classifying message: Error code: 401 - {'error': {'message': 'No auth credentials found', 'code': 401}}
2025-05-16 18:14:32,641 - __main__ - ERROR - Traceback (most recent call last):
  File "C:\Users\MohamedAlcafory\Desktop\TeleScrape\classifier.py", line 237, in classify_message
    response = make_api_request(client, model, messages)
               ^^^^^^^^^^^^^^^^^^^^^^^^^^^^^^^^^^^^^^^^^
  File "C:\Users\MohamedAlcafory\Desktop\TeleScrape\classifier.py", line 83, in wrapper
    raise e
  File "C:\Users\MohamedAlcafory\Desktop\TeleScrape\classifier.py", line 57, in wrapper
    return func(*args, **kwargs)
           ^^^^^^^^^^^^^^^^^^^^^
  File "C:\Users\MohamedAlcafory\Desktop\TeleScrape\classifier.py", line 114, in make_api_request
    response = client.chat.completions.create(
               ^^^^^^^^^^^^^^^^^^^^^^^^^^^^^^^
  File "C:\Users\MohamedAlcafory\Documents\TeleScrap\.venv\Lib\site-packages\openai\_utils\_utils.py", line 287, in wrapper
    return func(*args, **kwargs)
           ^^^^^^^^^^^^^^^^^^^^^
  File "C:\Users\MohamedAlcafory\Documents\TeleScrap\.venv\Lib\site-packages\openai\resources\chat\completions\completions.py", line 925, in create
    return self._post(
           ^^^^^^^^^^^
  File "C:\Users\MohamedAlcafory\Documents\TeleScrap\.venv\Lib\site-packages\openai\_base_client.py", line 1239, in post
    return cast(ResponseT, self.request(cast_to, opts, stream=stream, stream_cls=stream_cls))
                           ^^^^^^^^^^^^^^^^^^^^^^^^^^^^^^^^^^^^^^^^^^^^^^^^^^^^^^^^^^^^^^^^^
  File "C:\Users\MohamedAlcafory\Documents\TeleScrap\.venv\Lib\site-packages\openai\_base_client.py", line 1034, in request
    raise self._make_status_error_from_response(err.response) from None
openai.AuthenticationError: Error code: 401 - {'error': {'message': 'No auth credentials found', 'code': 401}}

2025-05-16 18:14:33,715 - __main__ - INFO - Sending request to model: deepseek/deepseek-chat-v3-0324:free
2025-05-16 18:14:34,015 - httpx - INFO - HTTP Request: POST https://openrouter.ai/api/v1/chat/completions "HTTP/1.1 401 Unauthorized"
2025-05-16 18:14:34,018 - __main__ - ERROR - Unexpected error: Error code: 401 - {'error': {'message': 'No auth credentials found', 'code': 401}}
2025-05-16 18:14:34,019 - __main__ - ERROR - Error during classification (attempt 1/3): Error code: 401 - {'error': {'message': 'No auth credentials found', 'code': 401}}
2025-05-16 18:14:36,259 - httpx - INFO - HTTP Request: POST https://openrouter.ai/api/v1/chat/completions "HTTP/1.1 401 Unauthorized"
2025-05-16 18:14:36,261 - __main__ - ERROR - Unexpected error: Error code: 401 - {'error': {'message': 'No auth credentials found', 'code': 401}}
2025-05-16 18:14:36,262 - __main__ - ERROR - Error during classification (attempt 2/3): Error code: 401 - {'error': {'message': 'No auth credentials found', 'code': 401}}
2025-05-16 18:14:38,496 - httpx - INFO - HTTP Request: POST https://openrouter.ai/api/v1/chat/completions "HTTP/1.1 401 Unauthorized"
2025-05-16 18:14:38,501 - __main__ - ERROR - Unexpected error: Error code: 401 - {'error': {'message': 'No auth credentials found', 'code': 401}}
2025-05-16 18:14:38,504 - __main__ - ERROR - Error during classification (attempt 3/3): Error code: 401 - {'error': {'message': 'No auth credentials found', 'code': 401}}
2025-05-16 18:14:38,507 - __main__ - ERROR - Error classifying message: Error code: 401 - {'error': {'message': 'No auth credentials found', 'code': 401}}
2025-05-16 18:14:38,510 - __main__ - ERROR - Traceback (most recent call last):
  File "C:\Users\MohamedAlcafory\Desktop\TeleScrape\classifier.py", line 237, in classify_message
    response = make_api_request(client, model, messages)
               ^^^^^^^^^^^^^^^^^^^^^^^^^^^^^^^^^^^^^^^^^
  File "C:\Users\MohamedAlcafory\Desktop\TeleScrape\classifier.py", line 83, in wrapper
    raise e
  File "C:\Users\MohamedAlcafory\Desktop\TeleScrape\classifier.py", line 57, in wrapper
    return func(*args, **kwargs)
           ^^^^^^^^^^^^^^^^^^^^^
  File "C:\Users\MohamedAlcafory\Desktop\TeleScrape\classifier.py", line 114, in make_api_request
    response = client.chat.completions.create(
               ^^^^^^^^^^^^^^^^^^^^^^^^^^^^^^^
  File "C:\Users\MohamedAlcafory\Documents\TeleScrap\.venv\Lib\site-packages\openai\_utils\_utils.py", line 287, in wrapper
    return func(*args, **kwargs)
           ^^^^^^^^^^^^^^^^^^^^^
  File "C:\Users\MohamedAlcafory\Documents\TeleScrap\.venv\Lib\site-packages\openai\resources\chat\completions\completions.py", line 925, in create
    return self._post(
           ^^^^^^^^^^^
  File "C:\Users\MohamedAlcafory\Documents\TeleScrap\.venv\Lib\site-packages\openai\_base_client.py", line 1239, in post
    return cast(ResponseT, self.request(cast_to, opts, stream=stream, stream_cls=stream_cls))
                           ^^^^^^^^^^^^^^^^^^^^^^^^^^^^^^^^^^^^^^^^^^^^^^^^^^^^^^^^^^^^^^^^^
  File "C:\Users\MohamedAlcafory\Documents\TeleScrap\.venv\Lib\site-packages\openai\_base_client.py", line 1034, in request
    raise self._make_status_error_from_response(err.response) from None
openai.AuthenticationError: Error code: 401 - {'error': {'message': 'No auth credentials found', 'code': 401}}

2025-05-16 18:14:39,538 - __main__ - INFO - Sending request to model: deepseek/deepseek-chat-v3-0324:free
2025-05-16 18:14:39,781 - httpx - INFO - HTTP Request: POST https://openrouter.ai/api/v1/chat/completions "HTTP/1.1 401 Unauthorized"
2025-05-16 18:14:39,781 - __main__ - ERROR - Unexpected error: Error code: 401 - {'error': {'message': 'No auth credentials found', 'code': 401}}
2025-05-16 18:14:39,782 - __main__ - ERROR - Error during classification (attempt 1/3): Error code: 401 - {'error': {'message': 'No auth credentials found', 'code': 401}}
2025-05-16 18:14:42,014 - httpx - INFO - HTTP Request: POST https://openrouter.ai/api/v1/chat/completions "HTTP/1.1 401 Unauthorized"
2025-05-16 18:14:42,017 - __main__ - ERROR - Unexpected error: Error code: 401 - {'error': {'message': 'No auth credentials found', 'code': 401}}
2025-05-16 18:14:42,017 - __main__ - ERROR - Error during classification (attempt 2/3): Error code: 401 - {'error': {'message': 'No auth credentials found', 'code': 401}}
2025-05-16 18:14:44,232 - httpx - INFO - HTTP Request: POST https://openrouter.ai/api/v1/chat/completions "HTTP/1.1 401 Unauthorized"
2025-05-16 18:14:44,237 - __main__ - ERROR - Unexpected error: Error code: 401 - {'error': {'message': 'No auth credentials found', 'code': 401}}
2025-05-16 18:14:44,240 - __main__ - ERROR - Error during classification (attempt 3/3): Error code: 401 - {'error': {'message': 'No auth credentials found', 'code': 401}}
2025-05-16 18:14:44,243 - __main__ - ERROR - Error classifying message: Error code: 401 - {'error': {'message': 'No auth credentials found', 'code': 401}}
2025-05-16 18:14:44,248 - __main__ - ERROR - Traceback (most recent call last):
  File "C:\Users\MohamedAlcafory\Desktop\TeleScrape\classifier.py", line 237, in classify_message
    response = make_api_request(client, model, messages)
               ^^^^^^^^^^^^^^^^^^^^^^^^^^^^^^^^^^^^^^^^^
  File "C:\Users\MohamedAlcafory\Desktop\TeleScrape\classifier.py", line 83, in wrapper
    raise e
  File "C:\Users\MohamedAlcafory\Desktop\TeleScrape\classifier.py", line 57, in wrapper
    return func(*args, **kwargs)
           ^^^^^^^^^^^^^^^^^^^^^
  File "C:\Users\MohamedAlcafory\Desktop\TeleScrape\classifier.py", line 114, in make_api_request
    response = client.chat.completions.create(
               ^^^^^^^^^^^^^^^^^^^^^^^^^^^^^^^
  File "C:\Users\MohamedAlcafory\Documents\TeleScrap\.venv\Lib\site-packages\openai\_utils\_utils.py", line 287, in wrapper
    return func(*args, **kwargs)
           ^^^^^^^^^^^^^^^^^^^^^
  File "C:\Users\MohamedAlcafory\Documents\TeleScrap\.venv\Lib\site-packages\openai\resources\chat\completions\completions.py", line 925, in create
    return self._post(
           ^^^^^^^^^^^
  File "C:\Users\MohamedAlcafory\Documents\TeleScrap\.venv\Lib\site-packages\openai\_base_client.py", line 1239, in post
    return cast(ResponseT, self.request(cast_to, opts, stream=stream, stream_cls=stream_cls))
                           ^^^^^^^^^^^^^^^^^^^^^^^^^^^^^^^^^^^^^^^^^^^^^^^^^^^^^^^^^^^^^^^^^
  File "C:\Users\MohamedAlcafory\Documents\TeleScrap\.venv\Lib\site-packages\openai\_base_client.py", line 1034, in request
    raise self._make_status_error_from_response(err.response) from None
openai.AuthenticationError: Error code: 401 - {'error': {'message': 'No auth credentials found', 'code': 401}}

2025-05-16 18:14:45,275 - __main__ - INFO - Sending request to model: deepseek/deepseek-chat-v3-0324:free
2025-05-16 18:14:45,495 - httpx - INFO - HTTP Request: POST https://openrouter.ai/api/v1/chat/completions "HTTP/1.1 401 Unauthorized"
2025-05-16 18:14:45,496 - __main__ - ERROR - Unexpected error: Error code: 401 - {'error': {'message': 'No auth credentials found', 'code': 401}}
2025-05-16 18:14:45,497 - __main__ - ERROR - Error during classification (attempt 1/3): Error code: 401 - {'error': {'message': 'No auth credentials found', 'code': 401}}
2025-05-16 18:14:47,732 - httpx - INFO - HTTP Request: POST https://openrouter.ai/api/v1/chat/completions "HTTP/1.1 401 Unauthorized"
2025-05-16 18:14:47,734 - __main__ - ERROR - Unexpected error: Error code: 401 - {'error': {'message': 'No auth credentials found', 'code': 401}}
2025-05-16 18:14:47,735 - __main__ - ERROR - Error during classification (attempt 2/3): Error code: 401 - {'error': {'message': 'No auth credentials found', 'code': 401}}
